concurrent.CountedCompleter.onExceptionalCompletion(Throwable ex,\n                       CountedCompleter<?> caller) throws an exception, and this task has not already\n otherwise completed normally.\n